2021-06-14 17:53:43,049 - _internal.py - WARNING - 225 -  * Running on all addresses.
   WARNING: This is a development server. Do not use it in a production deployment.
2021-06-14 17:53:43,050 - _internal.py - INFO - 225 -  * Running on http://172.18.0.107:5000/ (Press CTRL+C to quit)
2021-06-14 17:53:43,690 - main.py - ERROR - 78 - Exception while handling an update:
Traceback (most recent call last):
  File "/opt/virtualenvs/python3/lib/python3.8/site-packages/telegram/ext/dispatcher.py", line 555, in process_update
    handler.handle_update(update, self, check, context)
  File "/opt/virtualenvs/python3/lib/python3.8/site-packages/telegram/ext/handler.py", line 198, in handle_update
    return self.callback(update, context)
  File "/home/runner/Coronatracker/bot_funcs/commands.py", line 40, in start
    update.message.reply_text(msg)
  File "/opt/virtualenvs/python3/lib/python3.8/site-packages/telegram/message.py", line 764, in reply_text
    return self.bot.send_message(
  File "/opt/virtualenvs/python3/lib/python3.8/site-packages/telegram/bot.py", line 129, in decorator
    result = func(*args, **kwargs)
  File "/opt/virtualenvs/python3/lib/python3.8/site-packages/telegram/bot.py", line 499, in send_message
    return self._message(  # type: ignore[return-value]
  File "/opt/virtualenvs/python3/lib/python3.8/site-packages/telegram/ext/extbot.py", line 198, in _message
    result = super()._message(
  File "/opt/virtualenvs/python3/lib/python3.8/site-packages/telegram/bot.py", line 331, in _message
    result = self._post(endpoint, data, timeout=timeout, api_kwargs=api_kwargs)
  File "/opt/virtualenvs/python3/lib/python3.8/site-packages/telegram/bot.py", line 294, in _post
    return self.request.post(
  File "/opt/virtualenvs/python3/lib/python3.8/site-packages/telegram/utils/request.py", line 356, in post
    result = self._request_wrapper(
  File "/opt/virtualenvs/python3/lib/python3.8/site-packages/telegram/utils/request.py", line 277, in _request_wrapper
    raise Unauthorized(message)
telegram.error.Unauthorized: Forbidden: bot was blocked by the user
2021-06-14 17:53:44,187 - blocked.py - INFO - 12 - 
The user @ii_am_professor has blocked the bot, removing from database...


2021-06-14 17:53:44,188 - blocked.py - INFO - 14 - 
The user was removed from database.
2021-06-14 17:53:44,189 - blocked.py - INFO - 12 - 
The user @ryulive has blocked the bot, removing from database...


2021-06-14 17:53:44,189 - blocked.py - INFO - 14 - 
The user was removed from database.
2021-06-14 17:53:44,431 - utility.py - INFO - 54 - All data for all users is deleted!


2021-06-14 17:53:44,607 - alert.py - INFO - 54 - 
The breaking news was just sent to: (ง ͠° ͟ل͜ ͡°)ง for Bots.


2021-06-14 17:53:44,830 - alert.py - INFO - 54 - 
The breaking news was just sent to: H..


2021-06-14 17:53:45,033 - alert.py - INFO - 54 - 
The breaking news was just sent to: Harshil.


2021-06-14 17:53:45,195 - _internal.py - INFO - 225 - 172.18.0.1 - - [14/Jun/2021 17:53:45] "GET / HTTP/1.1" 200 -
2021-06-14 17:53:45,310 - alert.py - INFO - 54 - 
The breaking news was just sent to: sanganhchinh.


2021-06-14 17:53:45,430 - load_data.py - INFO - 136 - Beginning to download...
2021-06-14 17:53:45,586 - alert.py - INFO - 54 - 
The breaking news was just sent to: Samir.


2021-06-14 17:53:45,985 - alert.py - INFO - 54 - 
The breaking news was just sent to: Jaden.


2021-06-14 17:53:46,233 - alert.py - INFO - 54 - 
The breaking news was just sent to: Satya.


2021-06-14 17:53:46,310 - load_data.py - INFO - 153 - Downloaded and written to file!
2021-06-14 17:53:46,311 - load_data.py - INFO - 155 - Converting to sqlite database...
2021-06-14 17:53:46,495 - alert.py - INFO - 54 - 
The breaking news was just sent to: Ashwin.


2021-06-14 17:53:46,825 - alert.py - INFO - 54 - 
The breaking news was just sent to: Hitesh.


2021-06-14 17:53:47,044 - alert.py - INFO - 54 - 
The breaking news was just sent to: Roma.


2021-06-14 17:53:47,288 - alert.py - INFO - 54 - 
The breaking news was just sent to: Mohamed.


2021-06-14 17:53:47,321 - alert.py - INFO - 67 - 
Successfully updated breaking_url and sent_alert


2021-06-14 17:53:58,144 - load_data.py - INFO - 26 - Converted to sqlite database!
2021-06-14 17:53:58,153 - load_data.py - INFO - 159 - Deleted .csv file!
2021-06-14 17:53:58,153 - load_data.py - INFO - 162 - Last data get date updated!

2021-06-14 17:55:10,369 - commands.py - INFO - 31 - 
@Hoppingturtles just used /help in Harshil.


2021-06-14 17:55:16,990 - entry.py - INFO - 15 - 
@Hoppingturtles is using /graphs in Harshil
2021-06-14 17:55:23,813 - country_maker.py - INFO - 22 - @Hoppingturtles is on page 1.
2021-06-14 17:55:26,420 - country_maker.py - INFO - 22 - @Hoppingturtles is on page 2.
2021-06-14 17:55:28,115 - country_maker.py - INFO - 22 - @Hoppingturtles is on page 3.
2021-06-14 17:55:29,429 - country_maker.py - INFO - 22 - @Hoppingturtles is on page 4.
2021-06-14 17:55:34,442 - country_maker.py - INFO - 22 - @Hoppingturtles is on page 5.
2021-06-14 17:55:38,039 - country_maker.py - INFO - 22 - @Hoppingturtles is on page 4.
2021-06-14 17:55:40,864 - entry.py - INFO - 37 - @Hoppingturtles has selected India 🇮🇳.
2021-06-14 17:55:46,104 - trends_ui.py - INFO - 23 - @Hoppingturtles chose positivity_rate as the trend.
2021-06-14 17:55:46,341 - main.py - ERROR - 78 - Exception while handling an update:
Traceback (most recent call last):
  File "/opt/virtualenvs/python3/lib/python3.8/site-packages/telegram/ext/dispatcher.py", line 555, in process_update
    handler.handle_update(update, self, check, context)
  File "/opt/virtualenvs/python3/lib/python3.8/site-packages/telegram/ext/conversationhandler.py", line 626, in handle_update
    new_state = handler.handle_update(update, dispatcher, check_result, context)
  File "/opt/virtualenvs/python3/lib/python3.8/site-packages/telegram/ext/handler.py", line 198, in handle_update
    return self.callback(update, context)
  File "/home/runner/Coronatracker/graphing/ui/trends_ui.py", line 55, in chosen_trend
    update.message.reply_chat_action('upload_photo')  # Make user wait for a bit
AttributeError: 'NoneType' object has no attribute 'reply_chat_action'
2021-06-14 17:55:46,762 - dispatcher.py - ERROR - 573 - An uncaught error was raised while handling the error.
Traceback (most recent call last):
  File "/opt/virtualenvs/python3/lib/python3.8/site-packages/telegram/ext/dispatcher.py", line 555, in process_update
    handler.handle_update(update, self, check, context)
  File "/opt/virtualenvs/python3/lib/python3.8/site-packages/telegram/ext/conversationhandler.py", line 626, in handle_update
    new_state = handler.handle_update(update, dispatcher, check_result, context)
  File "/opt/virtualenvs/python3/lib/python3.8/site-packages/telegram/ext/handler.py", line 198, in handle_update
    return self.callback(update, context)
  File "/home/runner/Coronatracker/graphing/ui/trends_ui.py", line 55, in chosen_trend
    update.message.reply_chat_action('upload_photo')  # Make user wait for a bit
AttributeError: 'NoneType' object has no attribute 'reply_chat_action'

During handling of the above exception, another exception occurred:

Traceback (most recent call last):
  File "/opt/virtualenvs/python3/lib/python3.8/site-packages/telegram/ext/dispatcher.py", line 567, in process_update
    self.dispatch_error(update, exc)
  File "/opt/virtualenvs/python3/lib/python3.8/site-packages/telegram/ext/dispatcher.py", line 810, in dispatch_error
    callback(update, context)
  File "main.py", line 96, in errors
    context.bot.send_message(chat_id=476269395, text=message, parse_mode=ParseMode.HTML)
  File "/opt/virtualenvs/python3/lib/python3.8/site-packages/telegram/bot.py", line 129, in decorator
    result = func(*args, **kwargs)
  File "/opt/virtualenvs/python3/lib/python3.8/site-packages/telegram/bot.py", line 499, in send_message
    return self._message(  # type: ignore[return-value]
  File "/opt/virtualenvs/python3/lib/python3.8/site-packages/telegram/ext/extbot.py", line 198, in _message
    result = super()._message(
  File "/opt/virtualenvs/python3/lib/python3.8/site-packages/telegram/bot.py", line 331, in _message
    result = self._post(endpoint, data, timeout=timeout, api_kwargs=api_kwargs)
  File "/opt/virtualenvs/python3/lib/python3.8/site-packages/telegram/bot.py", line 294, in _post
    return self.request.post(
  File "/opt/virtualenvs/python3/lib/python3.8/site-packages/telegram/utils/request.py", line 356, in post
    result = self._request_wrapper(
  File "/opt/virtualenvs/python3/lib/python3.8/site-packages/telegram/utils/request.py", line 279, in _request_wrapper
    raise BadRequest(message)
telegram.error.BadRequest: Message is too long
2021-06-14 17:56:42,768 - _internal.py - INFO - 225 - 172.18.0.1 - - [14/Jun/2021 17:56:42] "GET / HTTP/1.1" 200 -
2021-06-14 17:57:12,005 - _internal.py - WARNING - 225 -  * Running on all addresses.
   WARNING: This is a development server. Do not use it in a production deployment.
2021-06-14 17:57:12,006 - _internal.py - INFO - 225 -  * Running on http://172.18.0.107:5000/ (Press CTRL+C to quit)
2021-06-14 17:57:12,217 - utility.py - INFO - 54 - All data for all users is deleted!


2021-06-14 17:57:12,363 - _internal.py - INFO - 225 - 172.18.0.1 - - [14/Jun/2021 17:57:12] "GET / HTTP/1.1" 200 -
2021-06-14 17:57:13,216 - load_data.py - INFO - 133 - Not time for updates yet.
2021-06-14 17:57:33,796 - entry.py - INFO - 15 - 
@Hoppingturtles is using /graphs in Harshil
2021-06-14 17:57:35,374 - country_maker.py - INFO - 22 - @Hoppingturtles is on page 1.
2021-06-14 17:57:37,474 - commands.py - INFO - 41 - 
@amitc50 just used /start in Amit.


2021-06-14 17:57:51,609 - entry.py - INFO - 15 - 
@amitc50 is using /graphs in Amit
2021-06-14 17:57:56,129 - country_maker.py - INFO - 22 - @amitc50 is on page 1.
2021-06-14 17:58:00,406 - country_maker.py - INFO - 22 - @amitc50 is on page 2.
2021-06-14 17:58:04,214 - country_maker.py - INFO - 22 - @amitc50 is on page 3.
2021-06-14 17:58:07,669 - country_maker.py - INFO - 22 - @amitc50 is on page 4.
2021-06-14 17:58:13,337 - entry.py - INFO - 37 - @amitc50 has selected India 🇮🇳.
2021-06-14 17:58:21,196 - trends_ui.py - INFO - 23 - @amitc50 chose new_cases as the trend.
2021-06-14 17:58:22,866 - font_manager.py - WARNING - 1350 - findfont: Font family ['Product Sans Bold'] not found. Falling back to DejaVu Sans.
2021-06-14 17:58:22,892 - font_manager.py - WARNING - 1350 - findfont: Font family ['Product Sans Regular'] not found. Falling back to DejaVu Sans.
2021-06-14 17:58:23,613 - font_manager.py - WARNING - 1350 - findfont: Font family ['Product Sans Bold'] not found. Falling back to DejaVu Sans.
2021-06-14 17:58:23,647 - font_manager.py - WARNING - 1350 - findfont: Font family ['Product Sans Medium'] not found. Falling back to DejaVu Sans.
2021-06-14 17:58:23,652 - font_manager.py - WARNING - 1350 - findfont: Font family ['Product Sans Regular'] not found. Falling back to DejaVu Sans.
2021-06-14 17:58:23,908 - font_manager.py - WARNING - 1350 - findfont: Font family ['Product Sans Bold'] not found. Falling back to DejaVu Sans.
2021-06-14 17:58:24,347 - main.py - ERROR - 78 - Exception while handling an update:
Traceback (most recent call last):
  File "/opt/virtualenvs/python3/lib/python3.8/site-packages/telegram/ext/dispatcher.py", line 555, in process_update
    handler.handle_update(update, self, check, context)
  File "/opt/virtualenvs/python3/lib/python3.8/site-packages/telegram/ext/conversationhandler.py", line 626, in handle_update
    new_state = handler.handle_update(update, dispatcher, check_result, context)
  File "/opt/virtualenvs/python3/lib/python3.8/site-packages/telegram/ext/handler.py", line 198, in handle_update
    return self.callback(update, context)
  File "/home/runner/Coronatracker/graphing/ui/trends_ui.py", line 76, in chosen_trend
    send_graph(update, context, x=context.user_data['trend_data'][0], y=y_data,
  File "/home/runner/Coronatracker/graphing/ui/trends_ui.py", line 108, in send_graph
    msg = update.message.reply_photo(photo=open(f"graphing/{pic}.png", "rb"), parse_mode="MarkdownV2",
AttributeError: 'NoneType' object has no attribute 'reply_photo'
2021-06-14 17:58:24,782 - dispatcher.py - ERROR - 573 - An uncaught error was raised while handling the error.
Traceback (most recent call last):
  File "/opt/virtualenvs/python3/lib/python3.8/site-packages/telegram/ext/dispatcher.py", line 555, in process_update
    handler.handle_update(update, self, check, context)
  File "/opt/virtualenvs/python3/lib/python3.8/site-packages/telegram/ext/conversationhandler.py", line 626, in handle_update
    new_state = handler.handle_update(update, dispatcher, check_result, context)
  File "/opt/virtualenvs/python3/lib/python3.8/site-packages/telegram/ext/handler.py", line 198, in handle_update
    return self.callback(update, context)
  File "/home/runner/Coronatracker/graphing/ui/trends_ui.py", line 76, in chosen_trend
    send_graph(update, context, x=context.user_data['trend_data'][0], y=y_data,
  File "/home/runner/Coronatracker/graphing/ui/trends_ui.py", line 108, in send_graph
    msg = update.message.reply_photo(photo=open(f"graphing/{pic}.png", "rb"), parse_mode="MarkdownV2",
AttributeError: 'NoneType' object has no attribute 'reply_photo'

During handling of the above exception, another exception occurred:

Traceback (most recent call last):
  File "/opt/virtualenvs/python3/lib/python3.8/site-packages/telegram/ext/dispatcher.py", line 567, in process_update
    self.dispatch_error(update, exc)
  File "/opt/virtualenvs/python3/lib/python3.8/site-packages/telegram/ext/dispatcher.py", line 810, in dispatch_error
    callback(update, context)
  File "main.py", line 96, in errors
    context.bot.send_message(chat_id=476269395, text=message, parse_mode=ParseMode.HTML)
  File "/opt/virtualenvs/python3/lib/python3.8/site-packages/telegram/bot.py", line 129, in decorator
    result = func(*args, **kwargs)
  File "/opt/virtualenvs/python3/lib/python3.8/site-packages/telegram/bot.py", line 499, in send_message
    return self._message(  # type: ignore[return-value]
  File "/opt/virtualenvs/python3/lib/python3.8/site-packages/telegram/ext/extbot.py", line 198, in _message
    result = super()._message(
  File "/opt/virtualenvs/python3/lib/python3.8/site-packages/telegram/bot.py", line 331, in _message
    result = self._post(endpoint, data, timeout=timeout, api_kwargs=api_kwargs)
  File "/opt/virtualenvs/python3/lib/python3.8/site-packages/telegram/bot.py", line 294, in _post
    return self.request.post(
  File "/opt/virtualenvs/python3/lib/python3.8/site-packages/telegram/utils/request.py", line 356, in post
    result = self._request_wrapper(
  File "/opt/virtualenvs/python3/lib/python3.8/site-packages/telegram/utils/request.py", line 279, in _request_wrapper
    raise BadRequest(message)
telegram.error.BadRequest: Message is too long
2021-06-14 17:59:27,731 - utility.py - INFO - 54 - All data for all users is deleted!


2021-06-14 17:59:28,011 - _internal.py - WARNING - 225 -  * Running on all addresses.
   WARNING: This is a development server. Do not use it in a production deployment.
2021-06-14 17:59:28,012 - _internal.py - INFO - 225 -  * Running on http://172.18.0.107:5000/ (Press CTRL+C to quit)
2021-06-14 17:59:28,384 - _internal.py - INFO - 225 - 172.18.0.1 - - [14/Jun/2021 17:59:28] "GET / HTTP/1.1" 200 -
2021-06-14 17:59:28,730 - load_data.py - INFO - 133 - Not time for updates yet.
2021-06-14 17:59:34,370 - entry.py - INFO - 15 - 
@Hoppingturtles is using /graphs in Harshil
2021-06-14 17:59:35,602 - country_maker.py - INFO - 22 - @Hoppingturtles is on page 1.
2021-06-14 17:59:37,254 - country_maker.py - INFO - 22 - @Hoppingturtles is on page 2.
2021-06-14 17:59:38,392 - country_maker.py - INFO - 22 - @Hoppingturtles is on page 3.
2021-06-14 17:59:38,948 - country_maker.py - INFO - 22 - @Hoppingturtles is on page 4.
2021-06-14 17:59:40,183 - country_maker.py - INFO - 22 - @Hoppingturtles is on page 5.
2021-06-14 17:59:41,399 - country_maker.py - INFO - 22 - @Hoppingturtles is on page 4.
2021-06-14 17:59:42,731 - entry.py - INFO - 37 - @Hoppingturtles has selected India 🇮🇳.
2021-06-14 17:59:45,049 - trends_ui.py - INFO - 23 - @Hoppingturtles chose positivity_rate as the trend.
2021-06-14 17:59:46,856 - font_manager.py - WARNING - 1350 - findfont: Font family ['Product Sans Bold'] not found. Falling back to DejaVu Sans.
2021-06-14 17:59:46,881 - font_manager.py - WARNING - 1350 - findfont: Font family ['Product Sans Regular'] not found. Falling back to DejaVu Sans.
2021-06-14 17:59:47,329 - font_manager.py - WARNING - 1350 - findfont: Font family ['Product Sans Bold'] not found. Falling back to DejaVu Sans.
2021-06-14 17:59:47,335 - font_manager.py - WARNING - 1350 - findfont: Font family ['Product Sans Medium'] not found. Falling back to DejaVu Sans.
2021-06-14 17:59:47,338 - font_manager.py - WARNING - 1350 - findfont: Font family ['Product Sans Regular'] not found. Falling back to DejaVu Sans.
2021-06-14 17:59:47,542 - font_manager.py - WARNING - 1350 - findfont: Font family ['Product Sans Bold'] not found. Falling back to DejaVu Sans.
2021-06-14 17:59:48,711 - trends_ui.py - INFO - 113 - 
The trend picture was just sent to: @Hoppingturtles.

2021-06-14 18:01:28,630 - trends_ui.py - INFO - 177 - @Hoppingturtles tried to toggle log scale for wrong graph.
2021-06-14 18:01:32,071 - main.py - ERROR - 78 - Exception while handling an update:
Traceback (most recent call last):
  File "/opt/virtualenvs/python3/lib/python3.8/site-packages/telegram/ext/dispatcher.py", line 555, in process_update
    handler.handle_update(update, self, check, context)
  File "/opt/virtualenvs/python3/lib/python3.8/site-packages/telegram/ext/conversationhandler.py", line 626, in handle_update
    new_state = handler.handle_update(update, dispatcher, check_result, context)
  File "/opt/virtualenvs/python3/lib/python3.8/site-packages/telegram/ext/handler.py", line 198, in handle_update
    return self.callback(update, context)
  File "/home/runner/Coronatracker/graphing/ui/navigation.py", line 42, in go_back_to_trend_buttons
    msg = update.message.reply_markdown_v2(msg, reply_markup=InlineKeyboardMarkup(graph_buttons))
AttributeError: 'NoneType' object has no attribute 'reply_markdown_v2'
2021-06-14 18:01:32,648 - dispatcher.py - ERROR - 573 - An uncaught error was raised while handling the error.
Traceback (most recent call last):
  File "/opt/virtualenvs/python3/lib/python3.8/site-packages/telegram/ext/dispatcher.py", line 555, in process_update
    handler.handle_update(update, self, check, context)
  File "/opt/virtualenvs/python3/lib/python3.8/site-packages/telegram/ext/conversationhandler.py", line 626, in handle_update
    new_state = handler.handle_update(update, dispatcher, check_result, context)
  File "/opt/virtualenvs/python3/lib/python3.8/site-packages/telegram/ext/handler.py", line 198, in handle_update
    return self.callback(update, context)
  File "/home/runner/Coronatracker/graphing/ui/navigation.py", line 42, in go_back_to_trend_buttons
    msg = update.message.reply_markdown_v2(msg, reply_markup=InlineKeyboardMarkup(graph_buttons))
AttributeError: 'NoneType' object has no attribute 'reply_markdown_v2'

During handling of the above exception, another exception occurred:

Traceback (most recent call last):
  File "/opt/virtualenvs/python3/lib/python3.8/site-packages/telegram/ext/dispatcher.py", line 567, in process_update
    self.dispatch_error(update, exc)
  File "/opt/virtualenvs/python3/lib/python3.8/site-packages/telegram/ext/dispatcher.py", line 810, in dispatch_error
    callback(update, context)
  File "main.py", line 96, in errors
    context.bot.send_message(chat_id=476269395, text=message, parse_mode=ParseMode.HTML)
  File "/opt/virtualenvs/python3/lib/python3.8/site-packages/telegram/bot.py", line 129, in decorator
    result = func(*args, **kwargs)
  File "/opt/virtualenvs/python3/lib/python3.8/site-packages/telegram/bot.py", line 499, in send_message
    return self._message(  # type: ignore[return-value]
  File "/opt/virtualenvs/python3/lib/python3.8/site-packages/telegram/ext/extbot.py", line 198, in _message
    result = super()._message(
  File "/opt/virtualenvs/python3/lib/python3.8/site-packages/telegram/bot.py", line 331, in _message
    result = self._post(endpoint, data, timeout=timeout, api_kwargs=api_kwargs)
  File "/opt/virtualenvs/python3/lib/python3.8/site-packages/telegram/bot.py", line 294, in _post
    return self.request.post(
  File "/opt/virtualenvs/python3/lib/python3.8/site-packages/telegram/utils/request.py", line 356, in post
    result = self._request_wrapper(
  File "/opt/virtualenvs/python3/lib/python3.8/site-packages/telegram/utils/request.py", line 279, in _request_wrapper
    raise BadRequest(message)
telegram.error.BadRequest: Message is too long
2021-06-14 18:16:10,642 - utility.py - INFO - 54 - All data for all users is deleted!


2021-06-14 18:16:10,687 - _internal.py - WARNING - 225 -  * Running on all addresses.
   WARNING: This is a development server. Do not use it in a production deployment.
2021-06-14 18:16:10,688 - _internal.py - INFO - 225 -  * Running on http://172.18.0.107:5000/ (Press CTRL+C to quit)
2021-06-14 18:16:11,052 - _internal.py - INFO - 225 - 172.18.0.1 - - [14/Jun/2021 18:16:11] "GET / HTTP/1.1" 200 -
2021-06-14 18:16:11,636 - load_data.py - INFO - 133 - Not time for updates yet.
2021-06-14 18:16:29,132 - entry.py - INFO - 15 - 
@Hoppingturtles is using /graphs in Harshil
2021-06-14 18:16:31,701 - country_maker.py - INFO - 22 - @Hoppingturtles is on page 1.
2021-06-14 18:16:39,562 - country_maker.py - INFO - 22 - @Hoppingturtles is on page 2.
2021-06-14 18:16:41,243 - country_maker.py - INFO - 22 - @Hoppingturtles is on page 3.
2021-06-14 18:16:43,140 - country_maker.py - INFO - 22 - @Hoppingturtles is on page 4.
2021-06-14 18:16:44,381 - entry.py - INFO - 37 - @Hoppingturtles has selected India 🇮🇳.
2021-06-14 18:16:46,695 - trends_ui.py - INFO - 23 - @Hoppingturtles chose new_tests as the trend.
2021-06-14 18:16:53,082 - font_manager.py - WARNING - 1350 - findfont: Font family ['Product Sans Bold'] not found. Falling back to DejaVu Sans.
2021-06-14 18:16:53,145 - font_manager.py - WARNING - 1350 - findfont: Font family ['Product Sans Regular'] not found. Falling back to DejaVu Sans.
2021-06-14 18:16:54,766 - font_manager.py - WARNING - 1350 - findfont: Font family ['Product Sans Bold'] not found. Falling back to DejaVu Sans.
2021-06-14 18:16:54,802 - font_manager.py - WARNING - 1350 - findfont: Font family ['Product Sans Medium'] not found. Falling back to DejaVu Sans.
2021-06-14 18:16:54,814 - font_manager.py - WARNING - 1350 - findfont: Font family ['Product Sans Regular'] not found. Falling back to DejaVu Sans.
2021-06-14 18:16:55,345 - font_manager.py - WARNING - 1350 - findfont: Font family ['Product Sans Bold'] not found. Falling back to DejaVu Sans.
2021-06-14 18:16:56,575 - trends_ui.py - INFO - 113 - 
The trend picture was just sent to: @Hoppingturtles.

2021-06-14 18:17:25,407 - trends_ui.py - INFO - 177 - @Hoppingturtles tried to toggle log scale for wrong graph.
2021-06-14 18:17:29,562 - navigation.py - INFO - 47 - @Hoppingturtles is now back in trend buttons.
2021-06-14 18:17:33,779 - navigation.py - INFO - 28 - @Hoppingturtles went back to the country list.
2021-06-14 18:17:33,779 - country_maker.py - INFO - 22 - @Hoppingturtles is on page 4.
2021-06-14 18:17:35,977 - navigation.py - INFO - 21 - @Hoppingturtles went back to the main menu.
2021-06-14 18:17:37,167 - entry.py - INFO - 37 - @Hoppingturtles has selected The World 🌎.
2021-06-14 18:17:47,894 - trends_ui.py - INFO - 23 - @Hoppingturtles chose new_cases as the trend.
2021-06-14 18:17:54,387 - trends_ui.py - INFO - 113 - 
The trend picture was just sent to: @Hoppingturtles.

2021-06-14 18:18:31,809 - navigation.py - INFO - 47 - @Hoppingturtles is now back in trend buttons.
2021-06-14 18:18:34,838 - navigation.py - INFO - 21 - @Hoppingturtles went back to the main menu.
2021-06-14 18:18:36,841 - commands.py - INFO - 121 - 
The user cancelled the request.


2021-06-14 18:18:37,082 - utility.py - INFO - 34 - The /graphs markup for @Hoppingturtles has been removed!


2021-06-14 18:18:37,090 - utility.py - INFO - 41 - All data for @Hoppingturtles is deleted!


2021-06-14 18:19:21,957 - commands.py - INFO - 80 - 
@Hoppingturtles just used /world in Harshil.


2021-06-14 18:20:06,276 - commands.py - INFO - 65 - 
@Hoppingturtles just used /uae in Harshil.


2021-06-14 18:20:47,611 - alert.py - INFO - 78 - 
@Hoppingturtles just used /alerts in Harshil.


2021-06-14 18:20:50,790 - alert.py - INFO - 100 - 
@Hoppingturtles just toggled /alerts in Harshil to ❌.


2021-06-14 18:20:52,651 - alert.py - INFO - 100 - 
@Hoppingturtles just toggled /alerts in Harshil to ✅.


2021-06-14 18:20:58,461 - commands.py - INFO - 85 - 
@Hoppingturtles just used /feedback in Harshil


2021-06-14 18:21:04,374 - commands.py - INFO - 97 - 
Feedback received from @Hoppingturtles:

Bot is slow
2021-06-14 18:21:22,248 - commands.py - INFO - 116 - 
@Hoppingturtles just used /vaccine in Harshil.


2021-06-14 18:22:31,583 - _internal.py - INFO - 225 - 172.18.0.1 - - [14/Jun/2021 18:22:31] "GET / HTTP/1.1" 200 -
